<?xml version="1.0"?>
<robot name="yumi" xmlns:xacro="http://www.ros.org/wiki/xacro">

    <!-- Import all Gazebo-customization elements, including Gazebo colors -->
    <xacro:include filename="$(find yumi_description)/urdf/Grippers/yumi_servo_gripper.gazebo.xacro" />
    <!-- Import Transmissions -->
    <xacro:include filename="$(find yumi_description)/urdf/Grippers/yumi_servo_gripper.transmission.xacro" />

    <xacro:include filename="$(find hector_xacro_tools)/urdf/inertia_tensors.urdf.xacro" />



    <!-- some constants -->
    <xacro:property name="joint_damping" value="0.5" />
    <xacro:property name="gripper_joint_damping" value="1.0" />
    <xacro:property name="max_gripper_effort" value="20"/>
    <xacro:property name="max_gripper_velocity" value="2"/>
    <xacro:property name="M_PI" value="3.1415926535897931" />
 
 
  <xacro:macro name="yumi_servo_gripper" params="parent name hardware_interface *origin">

    <!--joint between {parent} and base-->
    <joint name="${parent}_joint" type="fixed">
      <xacro:insert_block name="origin"/>
      <parent link="${parent}"/>
      <child link="${name}_base"/>
    </joint>

    <link name="${name}_base">
      <inertial>
        <origin xyz="0 0 0" rpy="0 0 0"/>
        <mass value="0.2"/>
        <inertia ixx="0.0001"  ixy="0"  ixz="0" iyy="0.0001" iyz="0" izz="0.0001" />
      </inertial>

      <visual>
        <origin xyz="0 0 0" rpy="0 0 0"/>
        <geometry>
          <xacro:if value="${(name == 'gripper_l')}">
            <mesh filename="package://yumi_description/meshes/gripper/base_with_case_l.stl"/>
          </xacro:if>
          <xacro:if value="${(name == 'gripper_r')}">
            <mesh filename="package://yumi_description/meshes/gripper/base_with_case_r.stl"/>
          </xacro:if>
        </geometry>
        <material name="Light_Grey"/>
      </visual>

      <collision>
        <origin xyz="0 0 0" rpy="0 0 0"/>
        <geometry>
          <xacro:if value="${(name == 'gripper_l')}">
            <mesh filename="package://yumi_description/meshes/gripper/coarse/base_with_case_l.stl"/>
          </xacro:if>
          <xacro:if value="${(name == 'gripper_r')}">
            <mesh filename="package://yumi_description/meshes/gripper/coarse/base_with_case_r.stl"/>
          </xacro:if>
        </geometry>
        <material name="Light_Grey"/>
      </collision>

    </link>

    <!-- joint between base and right finger -->
    <joint name="${name}_joint" type="prismatic">
      <parent link="${name}_base"/>
      <child link="${name}_finger_r"/>
      <origin xyz="0 -0.0065 0.0837" rpy="0 0 0"/>
      <axis xyz="-1 0 0"/>
      <limit lower="0" upper="0.025"
             effort="${max_gripper_effort}" velocity="${max_gripper_velocity}" />
      <dynamics damping="${gripper_joint_damping}"/>
    </joint>

    <link name="${name}_finger_r">
      <xacro:inertial_cuboid mass="0.04" x_length="0.05" y_length="0.05" z_length="0.05" />

      <visual>
        <origin xyz="0 0 0" rpy="0 0 0"/>
        <geometry>
          <mesh filename="package://yumi_description/meshes/gripper/finger_long.stl"/>
          <!-- <mesh filename="package://yumi_description/meshes/gripper/finger.stl"/> -->
        </geometry>
        <material name="Blue"/>
      </visual>

      <collision>
        <origin xyz="0 0 0" rpy="0 0 0"/>
        <geometry>
          <mesh filename="package://yumi_description/meshes/gripper/coarse/finger_long.stl"/>
          <!-- <mesh filename="package://yumi_description/meshes/gripper/coarse/finger.stl"/> -->
        </geometry>
        <material name="Blue"/>
      </collision>
    </link>

   <!-- joint between base and left finger -->
    <joint name="${name}_joint_m" type="prismatic">
      <parent link="${name}_base"/>
      <child link="${name}_finger_l"/>
      <origin xyz="0 0.0065 0.0837" rpy="0 0 ${PI}"/>
      <axis xyz="-1 0 0"/>
      <limit lower="0" upper="0.025"
             effort="${max_gripper_effort}" velocity="${max_gripper_velocity}" />
      <dynamics damping="${gripper_joint_damping}"/>
      <mimic joint="${name}_joint"/>
    </joint>

    <link name="${name}_finger_l">
      <xacro:inertial_cuboid mass="0.04" x_length="0.05" y_length="0.05" z_length="0.05" />
      <visual>
        <origin xyz="0 0 0" rpy="0 0 0"/>
        <geometry>
          <mesh filename="package://yumi_description/meshes/gripper/finger_long.stl"/>
          <!-- <mesh filename="package://yumi_description/meshes/gripper/finger.stl"/> -->
        </geometry>
        <material name="Blue"/>
      </visual>

      <collision>
        <origin xyz="0 0 0" rpy="0 0 0"/>
        <geometry>
          <mesh filename="package://yumi_description/meshes/gripper/coarse/finger_long.stl"/>
          <!-- <mesh filename="package://yumi_description/meshes/gripper/coarse/finger.stl"/> -->
        </geometry>
        <material name="Blue"/>
      </collision>
    </link>

    <!-- joint between body and camera -->
    <joint name="${name}_camera_joint" type="fixed">
      <parent link="${name}_base"/>
      <child link="${name}_camera_link"/>
      <xacro:if value="${(name == 'gripper_l')}">
        <origin xyz="0.0171 0.0533 0.0535" rpy="1.1805 -1.5625 -2.7600"/>
      </xacro:if>
      <xacro:if value="${(name == 'gripper_r')}">
        <origin xyz="-0.0115 -0.0544 0.0603" rpy="-0.3901 -1.5426 1.9291"/>
      </xacro:if>
    </joint>

    <link name="${name}_camera_link">
      <inertial>
        <origin xyz="0 0 0" rpy="0 0 0"/>
        <mass value="1"/>
        <inertia ixx="0.1"  ixy="0"  ixz="0" iyy="0.1" iyz="0" izz="0.1" />
      </inertial>

      <visual>
        <origin xyz="4.3e-3 -0.0175 0" rpy="${M_PI/2} 0 ${M_PI/2}"/>
        <geometry>
          <mesh filename="package://yumi_description/meshes/d435.dae" scale="1 1 1"/>
        </geometry>
        <material name="Grey"/>
      </visual>

      <collision>
        <origin xyz="0 -0.0175 0" rpy="0 0 0"/>
        <geometry>
          <box size="0.02505 0.090 0.025"/>
        </geometry>
      </collision>
    </link>

     <!--Extensions -->
    <xacro:yumi_servo_gripper_gazebo name="${name}" />
    <xacro:yumi_servo_gripper_transmission name="${name}" hardware_interface="${hardware_interface}"/>

  </xacro:macro>

</robot>
